### Tutorial: JavaScript Error Handling for Business

#### Introduction

Error handling is an essential part of writing robust and maintainable JavaScript code. It helps you manage and respond to runtime errors gracefully, ensuring your application can recover or provide meaningful feedback to users. This tutorial will cover try-catch blocks and error objects using business case examples. By mastering these concepts, you can create more resilient web applications.

#### Try-Catch Blocks

The try-catch block allows you to catch and handle errors that occur during code execution. It consists of a `try` block where you write your code and a `catch` block that handles any errors that occur within the `try` block.

##### Using Try-Catch

**Example**:
Suppose you need to handle errors when parsing JSON data received from a server.

```javascript
function parseJSON(data) {
    try {
        let parsedData = JSON.parse(data);
        console.log("Parsed Data:", parsedData);
    } catch (error) {
        console.error("Error parsing JSON:", error.message);
    }
}

let jsonData = '{"name":"John Doe","position":"Manager"}';
parseJSON(jsonData); // Output: Parsed Data: { name: 'John Doe', position: 'Manager' }

let invalidJsonData = '{"name":"John Doe", "position":"Manager"';
parseJSON(invalidJsonData); // Output: Error parsing JSON: Unexpected end of JSON input
```

**Explanation**:
In this example, the `parseJSON` function attempts to parse a JSON string using `JSON.parse()`. If the JSON string is valid, it prints the parsed data. If the JSON string is invalid, an error is thrown, and the `catch` block handles it by printing an error message. This ensures that your application can handle invalid JSON data gracefully.

##### Nested Try-Catch

You can use nested try-catch blocks to handle errors at different levels of your code.

**Example**:
Suppose you need to fetch data from an API and process it, with error handling at each step.

```javascript
function fetchData(apiUrl) {
    try {
        // Simulate fetching data from an API
        let response = '{ "name": "John Doe", "position": "Manager" }'; // Simulated response
        return JSON.parse(response);
    } catch (error) {
        console.error("Error fetching data:", error.message);
        throw new Error("Fetch data failed");
    }
}

function processData(apiUrl) {
    try {
        let data = fetchData(apiUrl);
        console.log("Processing data:", data);
    } catch (error) {
        console.error("Error processing data:", error.message);
    }
}

processData("https://api.example.com/data");
```

**Explanation**:
In this example, the `fetchData` function attempts to fetch and parse JSON data from an API. If parsing fails, it catches the error and throws a new error with a specific message. The `processData` function calls `fetchData` and processes the data if no errors occur. If `fetchData` throws an error, `processData` catches and logs it. This demonstrates how nested try-catch blocks can provide detailed error handling at different stages of your code.

#### Error Objects

Error objects provide detailed information about errors, including their name and message. You can create custom error objects to provide more meaningful error information.

##### Creating and Throwing Error Objects

**Example**:
Suppose you need to validate user input and throw custom errors if the input is invalid.

```javascript
function validateUserInput(user) {
    try {
        if (!user.name) {
            throw new Error("Name is required");
        }
        if (!user.email) {
            throw new Error("Email is required");
        }
        console.log("User input is valid");
    } catch (error) {
        console.error("Validation Error:", error.message);
    }
}

let userInput = { name: "Jane Doe", email: "" };
validateUserInput(userInput); // Output: Validation Error: Email is required
```

**Explanation**:
In this example, the `validateUserInput` function checks if the `user` object has a `name` and `email` property. If either property is missing, it throws a custom error with a specific message. The `catch` block handles the error and prints the validation error message. This approach allows you to provide detailed and meaningful error messages to users.

##### Custom Error Types

You can create custom error types by extending the built-in `Error` class.

**Example**:
Suppose you need to create a custom error type for handling authentication errors.

```javascript
class AuthenticationError extends Error {
    constructor(message) {
        super(message);
        this.name = "AuthenticationError";
    }
}

function authenticateUser(username, password) {
    try {
        if (!username || !password) {
            throw new AuthenticationError("Missing credentials");
        }
        if (username !== "admin" || password !== "admin123") {
            throw new AuthenticationError("Invalid credentials");
        }
        console.log("User authenticated successfully");
    } catch (error) {
        if (error instanceof AuthenticationError) {
            console.error("Authentication Error:", error.message);
        } else {
            console.error("Error:", error.message);
        }
    }
}

authenticateUser("", ""); // Output: Authentication Error: Missing credentials
authenticateUser("admin", "wrongpassword"); // Output: Authentication Error: Invalid credentials
authenticateUser("admin", "admin123"); // Output: User authenticated successfully
```

**Explanation**:
In this example, we create a custom error type `AuthenticationError` by extending the built-in `Error` class. The `authenticateUser` function checks if the `username` and `password` are provided and if they are correct. If there are any issues, it throws an `AuthenticationError` with a specific message. The `catch` block checks if the error is an instance of `AuthenticationError` and handles it accordingly. This approach allows you to create specific error types for different error scenarios, providing more precise error handling.

#### Finally Block

The `finally` block is optional and can be used to execute code after the `try` and `catch` blocks, regardless of whether an error occurred or not. This is useful for cleanup operations.

##### Using Finally Block

**Example**:
Suppose you need to ensure that a resource is released after attempting an operation, regardless of whether the operation succeeds or fails.

```javascript
function processData(data) {
    try {
        console.log("Processing data:", data);
        // Simulate an error
        if (!data) {
            throw new Error("No data provided");
        }
        // Process data...
    } catch (error) {
        console.error("Error processing data:", error.message);
    } finally {
        console.log("Releasing resources");
        // Release resources here
    }
}

processData("Sample data"); // Output: Processing data: Sample data \n Releasing resources
processData(null); // Output: Processing data: null \n Error processing data: No data provided \n Releasing resources
```

**Explanation**:
In this example, the `processData` function attempts to process the provided data. If no data is provided, it throws an error. Regardless of whether an error occurs, the `finally` block executes, ensuring that resources are released. This approach ensures that cleanup operations are performed even if an error occurs.

#### Conclusion

By understanding and using try-catch blocks, error objects, and the finally block in JavaScript through these business-related examples, you can create robust and resilient web applications that handle errors gracefully. Practice these concepts to build a strong foundation in JavaScript error handling.

### Further Reading
- [MDN Web Docs: Error Handling](https://developer.mozilla.org/en-US/docs/Web/JavaScript/Guide/Control_flow_and_error_handling#Exception_handling_statements)
- [JavaScript.info: Error Handling](https://javascript.info/try-catch)
- [Eloquent JavaScript: Error Handling](https://eloquentjavascript.net/08_error.html)
- [MDN Web Docs: Error](https://developer.mozilla.org/en-US/docs/Web/JavaScript/Reference/Global_Objects/Error)